01-20 13:12:00  INFO Talon starting with /Users/evan/.talon
01-20 13:12:01 DEBUG [+] /Applications/Talon.app/Contents/Resources/plugins/eye.py
01-20 13:12:01 ERROR eye (/Applications/Talon.app/Contents/Resources/plugins/eye.py) import failed
Traceback (most recent call last):
  File "/Applications/Talon.app/Contents/Resources/loader.py", line 40, in load
    spec.loader.exec_module(module)
  File "<builtin>/frozen importlib._bootstrap_external", line 686, in exec_module
  File "<frozen importlib._bootstrap>", line 223, in _call_with_frames_removed
  File "/Applications/Talon.app/Contents/Resources/plugins/eye.py", line 158, in <module>
    tracker = eye.Eye()
  File "/Applications/Talon.app/Contents/Resources/pypy/site-packages/talon/eye.py", line 138, in __init__
    raise EyeOpenErr('Eye Tracker failed to open')
talon.eye.EyeOpenErr: Eye Tracker failed to open
01-20 13:12:01 DEBUG [+] /Applications/Talon.app/Contents/Resources/plugins/repl.py
01-20 13:12:01 DEBUG [+] /Users/evan/.talon/user/std.py
01-20 13:12:11    IO Exception in thread Thread-3:
Traceback (most recent call last):
  File "/Applications/Talon.app/Contents/Resources/pypy/lib-python/3/threading.py", line 914, in _bootstrap_inner
    self.run()
  File "/Applications/Talon.app/Contents/Resources/pypy/lib-python/3/threading.py", line 862, in run
    self._target(*self._args, **self._kwargs)
  File "/Applications/Talon.app/Contents/Resources/pypy/site-packages/talon/engine.py", line 58, in check_ready
    j = self.cmd('status')
  File "/Applications/Talon.app/Contents/Resources/pypy/site-packages/talon/engine.py", line 98, in cmd
    raise EngineCmdErr('engine command "{}" failed'.format(cmd))
talon.engine.EngineCmdErr: engine command "status" failed
01-20 13:12:11    IO 
01-20 13:16:54 DEBUG [~] /Users/evan/.talon/user/std.py
01-20 13:17:43 DEBUG [~] /Users/evan/.talon/user/std.py
01-20 13:18:33  INFO Talon starting with /Users/evan/.talon
01-20 13:18:34 DEBUG [+] /Applications/Talon.app/Contents/Resources/plugins/eye.py
01-20 13:18:34 ERROR eye (/Applications/Talon.app/Contents/Resources/plugins/eye.py) import failed
Traceback (most recent call last):
  File "/Applications/Talon.app/Contents/Resources/loader.py", line 40, in load
    spec.loader.exec_module(module)
  File "<builtin>/frozen importlib._bootstrap_external", line 686, in exec_module
  File "<frozen importlib._bootstrap>", line 223, in _call_with_frames_removed
  File "/Applications/Talon.app/Contents/Resources/plugins/eye.py", line 158, in <module>
    tracker = eye.Eye()
  File "/Applications/Talon.app/Contents/Resources/pypy/site-packages/talon/eye.py", line 138, in __init__
    raise EyeOpenErr('Eye Tracker failed to open')
talon.eye.EyeOpenErr: Eye Tracker failed to open
01-20 13:18:34 DEBUG [+] /Applications/Talon.app/Contents/Resources/plugins/repl.py
01-20 13:18:34 DEBUG [+] /Users/evan/.talon/user/std.py
01-20 13:22:17 DEBUG [~] /Users/evan/.talon/user/std.py
01-20 13:26:09  INFO Talon starting with /Users/evan/.talon
01-20 13:26:09 DEBUG [+] /Applications/Talon.app/Contents/Resources/plugins/eye.py
01-20 13:26:09 ERROR eye (/Applications/Talon.app/Contents/Resources/plugins/eye.py) import failed
Traceback (most recent call last):
  File "/Applications/Talon.app/Contents/Resources/loader.py", line 40, in load
    spec.loader.exec_module(module)
  File "<builtin>/frozen importlib._bootstrap_external", line 686, in exec_module
  File "<frozen importlib._bootstrap>", line 223, in _call_with_frames_removed
  File "/Applications/Talon.app/Contents/Resources/plugins/eye.py", line 158, in <module>
    tracker = eye.Eye()
  File "/Applications/Talon.app/Contents/Resources/pypy/site-packages/talon/eye.py", line 138, in __init__
    raise EyeOpenErr('Eye Tracker failed to open')
talon.eye.EyeOpenErr: Eye Tracker failed to open
01-20 13:26:09 DEBUG [+] /Applications/Talon.app/Contents/Resources/plugins/repl.py
01-20 13:26:09 DEBUG [+] /Users/evan/.talon/user/python.py
01-20 13:26:09 DEBUG [+] /Users/evan/.talon/user/std.py
01-20 13:26:09 DEBUG [+] /Users/evan/.talon/user/vim.py
01-20 13:27:57 DEBUG [~] /Users/evan/.talon/user/python.py
01-20 13:28:11 DEBUG [~] /Users/evan/.talon/user/python.py
01-20 13:29:25 DEBUG [~] /Users/evan/.talon/user/python.py
01-20 13:29:27 DEBUG [~] /Users/evan/.talon/user/python.py
01-20 13:31:50 DEBUG [~] /Users/evan/.talon/user/vim.py
01-20 13:31:50 ERROR user.vim (/Users/evan/.talon/user/vim.py) unload failed
Traceback (most recent call last):
  File "/Applications/Talon.app/Contents/Resources/loader.py", line 24, in load
    module.unload()
  File "/Users/evan/.talon/user/vim.py", line 136, in unload
    ctx.disable()
AttributeError: 'Context' object has no attribute 'disable'
01-20 13:31:50 ERROR user.vim (/Users/evan/.talon/user/vim.py) reload failed
Traceback (most recent call last):
  File "/Applications/Talon.app/Contents/Resources/loader.py", line 28, in load
    module = importlib.reload(self[path])
  File "/Applications/Talon.app/Contents/Resources/pypy/lib-python/3/importlib/__init__.py", line 166, in reload
    _bootstrap._exec(spec, module)
  File "<frozen importlib._bootstrap>", line 627, in _exec
  File "<builtin>/frozen importlib._bootstrap_external", line 686, in exec_module
  File "<frozen importlib._bootstrap>", line 223, in _call_with_frames_removed
  File "/Users/evan/.talon/user/vim.py", line 2, in <module>
    ctx = Context('vim', name='iTerm2', func=lambda app, win: 'vim' in win.title)
TypeError: __init__() got multiple values for argument 'name'
01-20 13:43:04 DEBUG [~] /Users/evan/.talon/user/vim.py
01-20 13:43:04 ERROR user.vim (/Users/evan/.talon/user/vim.py) unload failed
Traceback (most recent call last):
  File "/Applications/Talon.app/Contents/Resources/loader.py", line 24, in load
    module.unload()
  File "/Users/evan/.talon/user/vim.py", line 136, in unload
    ctx.disable()
AttributeError: 'Context' object has no attribute 'disable'
01-20 13:43:04 ERROR user.vim (/Users/evan/.talon/user/vim.py) reload failed
Traceback (most recent call last):
  File "/Applications/Talon.app/Contents/Resources/loader.py", line 28, in load
    module = importlib.reload(self[path])
  File "/Applications/Talon.app/Contents/Resources/pypy/lib-python/3/importlib/__init__.py", line 166, in reload
    _bootstrap._exec(spec, module)
  File "<frozen importlib._bootstrap>", line 627, in _exec
  File "<builtin>/frozen importlib._bootstrap_external", line 682, in exec_module
  File "<builtin>/frozen importlib._bootstrap_external", line 788, in get_code
  File "<builtin>/frozen importlib._bootstrap_external", line 748, in source_to_code
  File "<frozen importlib._bootstrap>", line 223, in _call_with_frames_removed
  File "/Users/evan/.talon/user/vim.py", line 4
    From .python import pythonmap
                ^
SyntaxError: invalid syntax
01-20 13:43:07 DEBUG [~] /Users/evan/.talon/user/vim.py
01-20 13:43:07 ERROR user.vim (/Users/evan/.talon/user/vim.py) unload failed
Traceback (most recent call last):
  File "/Applications/Talon.app/Contents/Resources/loader.py", line 24, in load
    module.unload()
  File "/Users/evan/.talon/user/vim.py", line 136, in unload
    ctx.disable()
AttributeError: 'Context' object has no attribute 'disable'
01-20 13:43:07 ERROR user.vim (/Users/evan/.talon/user/vim.py) reload failed
Traceback (most recent call last):
  File "/Applications/Talon.app/Contents/Resources/loader.py", line 28, in load
    module = importlib.reload(self[path])
  File "/Applications/Talon.app/Contents/Resources/pypy/lib-python/3/importlib/__init__.py", line 166, in reload
    _bootstrap._exec(spec, module)
  File "<frozen importlib._bootstrap>", line 627, in _exec
  File "<builtin>/frozen importlib._bootstrap_external", line 682, in exec_module
  File "<builtin>/frozen importlib._bootstrap_external", line 788, in get_code
  File "<builtin>/frozen importlib._bootstrap_external", line 748, in source_to_code
  File "<frozen importlib._bootstrap>", line 223, in _call_with_frames_removed
  File "/Users/evan/.talon/user/vim.py", line 4
    From .python import pythonmap
                ^
SyntaxError: invalid syntax
01-20 13:43:19 DEBUG [~] /Users/evan/.talon/user/vim.py
01-20 13:43:19 ERROR user.vim (/Users/evan/.talon/user/vim.py) unload failed
Traceback (most recent call last):
  File "/Applications/Talon.app/Contents/Resources/loader.py", line 24, in load
    module.unload()
  File "/Users/evan/.talon/user/vim.py", line 136, in unload
    ctx.disable()
AttributeError: 'Context' object has no attribute 'disable'
01-20 13:43:19 ERROR user.vim (/Users/evan/.talon/user/vim.py) reload failed
Traceback (most recent call last):
  File "/Applications/Talon.app/Contents/Resources/loader.py", line 28, in load
    module = importlib.reload(self[path])
  File "/Applications/Talon.app/Contents/Resources/pypy/lib-python/3/importlib/__init__.py", line 166, in reload
    _bootstrap._exec(spec, module)
  File "<frozen importlib._bootstrap>", line 627, in _exec
  File "<builtin>/frozen importlib._bootstrap_external", line 686, in exec_module
  File "<frozen importlib._bootstrap>", line 223, in _call_with_frames_removed
  File "/Users/evan/.talon/user/vim.py", line 2, in <module>
    ctx = Context('vim', name='com.apple.Terminal', func=lambda app, win: 'vim' in win.title)
TypeError: __init__() got multiple values for argument 'name'
01-20 13:43:28 DEBUG [~] /Users/evan/.talon/user/vim.py
01-20 13:43:28 ERROR user.vim (/Users/evan/.talon/user/vim.py) unload failed
Traceback (most recent call last):
  File "/Applications/Talon.app/Contents/Resources/loader.py", line 24, in load
    module.unload()
  File "/Users/evan/.talon/user/vim.py", line 136, in unload
    ctx.disable()
AttributeError: 'Context' object has no attribute 'disable'
01-20 13:43:28 ERROR user.vim (/Users/evan/.talon/user/vim.py) reload failed
Traceback (most recent call last):
  File "/Applications/Talon.app/Contents/Resources/loader.py", line 28, in load
    module = importlib.reload(self[path])
  File "/Applications/Talon.app/Contents/Resources/pypy/lib-python/3/importlib/__init__.py", line 166, in reload
    _bootstrap._exec(spec, module)
  File "<frozen importlib._bootstrap>", line 627, in _exec
  File "<builtin>/frozen importlib._bootstrap_external", line 686, in exec_module
  File "<frozen importlib._bootstrap>", line 223, in _call_with_frames_removed
  File "/Users/evan/.talon/user/vim.py", line 2, in <module>
    ctx = Context('vim', name='com.apple.Terminal', func=lambda app, win: 'vi' in win.title)
TypeError: __init__() got multiple values for argument 'name'
01-20 13:43:29 DEBUG [~] /Users/evan/.talon/user/vim.py
01-20 13:43:29 ERROR user.vim (/Users/evan/.talon/user/vim.py) unload failed
Traceback (most recent call last):
  File "/Applications/Talon.app/Contents/Resources/loader.py", line 24, in load
    module.unload()
  File "/Users/evan/.talon/user/vim.py", line 136, in unload
    ctx.disable()
AttributeError: 'Context' object has no attribute 'disable'
01-20 13:43:29 ERROR user.vim (/Users/evan/.talon/user/vim.py) reload failed
Traceback (most recent call last):
  File "/Applications/Talon.app/Contents/Resources/loader.py", line 28, in load
    module = importlib.reload(self[path])
  File "/Applications/Talon.app/Contents/Resources/pypy/lib-python/3/importlib/__init__.py", line 166, in reload
    _bootstrap._exec(spec, module)
  File "<frozen importlib._bootstrap>", line 627, in _exec
  File "<builtin>/frozen importlib._bootstrap_external", line 686, in exec_module
  File "<frozen importlib._bootstrap>", line 223, in _call_with_frames_removed
  File "/Users/evan/.talon/user/vim.py", line 2, in <module>
    ctx = Context('vim', name='com.apple.Terminal', func=lambda app, win: 'vi' in win.title)
TypeError: __init__() got multiple values for argument 'name'
01-20 13:49:12  INFO Talon starting with /Users/evan/.talon
01-20 13:49:13 DEBUG [+] /Applications/Talon.app/Contents/Resources/plugins/eye.py
01-20 13:49:13 ERROR eye (/Applications/Talon.app/Contents/Resources/plugins/eye.py) import failed
Traceback (most recent call last):
  File "/Applications/Talon.app/Contents/Resources/loader.py", line 40, in load
    spec.loader.exec_module(module)
  File "<builtin>/frozen importlib._bootstrap_external", line 686, in exec_module
  File "<frozen importlib._bootstrap>", line 223, in _call_with_frames_removed
  File "/Applications/Talon.app/Contents/Resources/plugins/eye.py", line 158, in <module>
    tracker = eye.Eye()
  File "/Applications/Talon.app/Contents/Resources/pypy/site-packages/talon/eye.py", line 138, in __init__
    raise EyeOpenErr('Eye Tracker failed to open')
talon.eye.EyeOpenErr: Eye Tracker failed to open
01-20 13:49:13 DEBUG [+] /Applications/Talon.app/Contents/Resources/plugins/repl.py
01-20 13:49:13 DEBUG [+] /Users/evan/.talon/user/python.py
01-20 13:49:13 DEBUG [+] /Users/evan/.talon/user/std.py
01-20 13:49:13 DEBUG [+] /Users/evan/.talon/user/vim.py
01-20 13:49:13 ERROR user.vim (/Users/evan/.talon/user/vim.py) import failed
Traceback (most recent call last):
  File "/Applications/Talon.app/Contents/Resources/loader.py", line 40, in load
    spec.loader.exec_module(module)
  File "<builtin>/frozen importlib._bootstrap_external", line 686, in exec_module
  File "<frozen importlib._bootstrap>", line 223, in _call_with_frames_removed
  File "/Users/evan/.talon/user/vim.py", line 2, in <module>
    ctx = Context('vim', name='com.googlecode.iterm2', func=lambda app, win: 'vi' in win.title)
TypeError: __init__() got multiple values for argument 'name'
01-20 13:50:10 DEBUG [+] /Users/evan/.talon/user/vim.py
01-20 13:50:10 ERROR user.vim (/Users/evan/.talon/user/vim.py) import failed
Traceback (most recent call last):
  File "/Applications/Talon.app/Contents/Resources/loader.py", line 40, in load
    spec.loader.exec_module(module)
  File "<builtin>/frozen importlib._bootstrap_external", line 686, in exec_module
  File "<frozen importlib._bootstrap>", line 223, in _call_with_frames_removed
  File "/Users/evan/.talon/user/vim.py", line 2, in <module>
    ctx = Context('vim', name='com.googlecode.iterm2', func=lambda app, win: 'vim' in win.title)
TypeError: __init__() got multiple values for argument 'name'
01-20 13:50:31 DEBUG [+] /Users/evan/.talon/user/vim.py
01-20 18:11:52  INFO Talon starting with /Users/evan/.talon
01-20 18:11:52 DEBUG [+] /Applications/Talon.app/Contents/Resources/plugins/eye.py
01-20 18:11:52 ERROR eye (/Applications/Talon.app/Contents/Resources/plugins/eye.py) import failed
Traceback (most recent call last):
  File "/Applications/Talon.app/Contents/Resources/loader.py", line 40, in load
    spec.loader.exec_module(module)
  File "<builtin>/frozen importlib._bootstrap_external", line 686, in exec_module
  File "<frozen importlib._bootstrap>", line 223, in _call_with_frames_removed
  File "/Applications/Talon.app/Contents/Resources/plugins/eye.py", line 158, in <module>
    tracker = eye.Eye()
  File "/Applications/Talon.app/Contents/Resources/pypy/site-packages/talon/eye.py", line 138, in __init__
    raise EyeOpenErr('Eye Tracker failed to open')
talon.eye.EyeOpenErr: Eye Tracker failed to open
01-20 18:11:52 DEBUG [+] /Applications/Talon.app/Contents/Resources/plugins/repl.py
01-20 18:11:52 DEBUG [+] /Users/evan/.talon/user/python.py
01-20 18:11:52 DEBUG [+] /Users/evan/.talon/user/std.py
01-20 18:11:52 DEBUG [+] /Users/evan/.talon/user/vim.py
01-20 18:13:37 DEBUG [~] /Users/evan/.talon/user/std.py
01-20 18:15:22 DEBUG [~] /Users/evan/.talon/user/std.py
01-20 18:16:08 DEBUG [~] /Users/evan/.talon/user/std.py
01-20 18:19:12 DEBUG [~] /Users/evan/.talon/user/std.py
01-20 18:19:12 ERROR user.std (/Users/evan/.talon/user/std.py) reload failed
Traceback (most recent call last):
  File "/Applications/Talon.app/Contents/Resources/loader.py", line 28, in load
    module = importlib.reload(self[path])
  File "/Applications/Talon.app/Contents/Resources/pypy/lib-python/3/importlib/__init__.py", line 166, in reload
    _bootstrap._exec(spec, module)
  File "<frozen importlib._bootstrap>", line 627, in _exec
  File "<builtin>/frozen importlib._bootstrap_external", line 682, in exec_module
  File "<builtin>/frozen importlib._bootstrap_external", line 788, in get_code
  File "<builtin>/frozen importlib._bootstrap_external", line 748, in source_to_code
  File "<frozen importlib._bootstrap>", line 223, in _call_with_frames_removed
  File "/Users/evan/.talon/user/std.py", line 167
    'empty list': '[]',
    ^
SyntaxError: invalid syntax
01-20 18:19:53 DEBUG [~] /Users/evan/.talon/user/std.py
01-20 18:19:53 ERROR user.std (/Users/evan/.talon/user/std.py) reload failed
Traceback (most recent call last):
  File "/Applications/Talon.app/Contents/Resources/loader.py", line 28, in load
    module = importlib.reload(self[path])
  File "/Applications/Talon.app/Contents/Resources/pypy/lib-python/3/importlib/__init__.py", line 166, in reload
    _bootstrap._exec(spec, module)
  File "<frozen importlib._bootstrap>", line 627, in _exec
  File "<builtin>/frozen importlib._bootstrap_external", line 682, in exec_module
  File "<builtin>/frozen importlib._bootstrap_external", line 788, in get_code
  File "<builtin>/frozen importlib._bootstrap_external", line 748, in source_to_code
  File "<frozen importlib._bootstrap>", line 223, in _call_with_frames_removed
  File "/Users/evan/.talon/user/std.py", line 167
    'empty list': '[]',
    ^
SyntaxError: invalid syntax
01-20 18:19:56 DEBUG [~] /Users/evan/.talon/user/std.py
01-20 18:20:26 DEBUG [~] /Users/evan/.talon/user/std.py
01-20 18:25:05 DEBUG [~] /Users/evan/.talon/user/std.py
01-20 18:25:36 DEBUG [~] /Users/evan/.talon/user/vim.py
01-20 18:25:36 ERROR user.vim (/Users/evan/.talon/user/vim.py) unload failed
Traceback (most recent call last):
  File "/Applications/Talon.app/Contents/Resources/loader.py", line 24, in load
    module.unload()
  File "/Users/evan/.talon/user/vim.py", line 136, in unload
    ctx.disable()
AttributeError: 'Context' object has no attribute 'disable'
01-20 18:25:37 DEBUG [~] /Users/evan/.talon/user/vim.py
01-20 18:25:37 ERROR user.vim (/Users/evan/.talon/user/vim.py) unload failed
Traceback (most recent call last):
  File "/Applications/Talon.app/Contents/Resources/loader.py", line 24, in load
    module.unload()
  File "/Users/evan/.talon/user/vim.py", line 136, in unload
    ctx.disable()
AttributeError: 'Context' object has no attribute 'disable'
01-20 18:25:42 DEBUG [~] /Users/evan/.talon/user/vim.py
01-20 18:25:42 ERROR user.vim (/Users/evan/.talon/user/vim.py) unload failed
Traceback (most recent call last):
  File "/Applications/Talon.app/Contents/Resources/loader.py", line 24, in load
    module.unload()
  File "/Users/evan/.talon/user/vim.py", line 136, in unload
    ctx.disable()
AttributeError: 'Context' object has no attribute 'disable'
01-20 18:27:06 DEBUG [~] /Users/evan/.talon/user/vim.py
01-20 18:27:06 ERROR user.vim (/Users/evan/.talon/user/vim.py) unload failed
Traceback (most recent call last):
  File "/Applications/Talon.app/Contents/Resources/loader.py", line 24, in load
    module.unload()
  File "/Users/evan/.talon/user/vim.py", line 136, in unload
AttributeError: 'Context' object has no attribute 'disable'
01-20 18:31:38 DEBUG [~] /Users/evan/.talon/user/vim.py
01-20 18:31:38 ERROR user.vim (/Users/evan/.talon/user/vim.py) unload failed
Traceback (most recent call last):
  File "/Applications/Talon.app/Contents/Resources/loader.py", line 24, in load
    module.unload()
  File "/Users/evan/.talon/user/vim.py", line 134, in unload
    ctx.disable()
AttributeError: 'Context' object has no attribute 'disable'
01-20 18:33:56 DEBUG [+] /Users/evan/.talon/user/bash.py
01-20 18:34:22 DEBUG [~] /Users/evan/.talon/user/vim.py
01-20 18:34:22 ERROR user.vim (/Users/evan/.talon/user/vim.py) unload failed
Traceback (most recent call last):
  File "/Applications/Talon.app/Contents/Resources/loader.py", line 24, in load
    module.unload()
  File "/Users/evan/.talon/user/vim.py", line 134, in unload
AttributeError: 'Context' object has no attribute 'disable'
01-20 18:38:14 DEBUG [~] /Users/evan/.talon/user/bash.py
01-20 18:47:26 DEBUG [~] /Users/evan/.talon/user/python.py
01-20 18:47:26 ERROR user.python (/Users/evan/.talon/user/python.py) reload failed
Traceback (most recent call last):
  File "/Applications/Talon.app/Contents/Resources/loader.py", line 28, in load
    module = importlib.reload(self[path])
  File "/Applications/Talon.app/Contents/Resources/pypy/lib-python/3/importlib/__init__.py", line 166, in reload
    _bootstrap._exec(spec, module)
  File "<frozen importlib._bootstrap>", line 627, in _exec
  File "<builtin>/frozen importlib._bootstrap_external", line 686, in exec_module
  File "<frozen importlib._bootstrap>", line 223, in _call_with_frames_removed
  File "/Users/evan/.talon/user/python.py", line 52, in <module>
    ctx.keymap(python)
NameError: name 'python' is not defined
01-20 18:48:38 DEBUG [~] /Users/evan/.talon/user/python.py
01-20 18:48:49 DEBUG [~] /Users/evan/.talon/user/python.py
01-20 18:48:49 ERROR user.python (/Users/evan/.talon/user/python.py) unload failed
Traceback (most recent call last):
  File "/Applications/Talon.app/Contents/Resources/loader.py", line 24, in load
    module.unload()
  File "/Users/evan/.talon/user/python.py", line 57, in unload
    ctx.disable()
AttributeError: 'Context' object has no attribute 'disable'
01-20 18:48:57 DEBUG [~] /Users/evan/.talon/user/python.py
01-20 18:48:57 ERROR user.python (/Users/evan/.talon/user/python.py) unload failed
Traceback (most recent call last):
  File "/Applications/Talon.app/Contents/Resources/loader.py", line 24, in load
    module.unload()
  File "/Users/evan/.talon/user/python.py", line 57, in unload
    ctx.disable()
AttributeError: 'Context' object has no attribute 'disable'
01-20 18:50:27 DEBUG [~] /Users/evan/.talon/user/python.py
01-20 18:50:27 ERROR user.python (/Users/evan/.talon/user/python.py) unload failed
Traceback (most recent call last):
  File "/Applications/Talon.app/Contents/Resources/loader.py", line 24, in load
    module.unload()
  File "/Users/evan/.talon/user/python.py", line 57, in unload
    ctx.disable()
AttributeError: 'Context' object has no attribute 'disable'
01-20 18:50:58 DEBUG [~] /Users/evan/.talon/user/python.py
01-20 18:50:58 ERROR user.python (/Users/evan/.talon/user/python.py) unload failed
Traceback (most recent call last):
  File "/Applications/Talon.app/Contents/Resources/loader.py", line 24, in load
    module.unload()
  File "/Users/evan/.talon/user/python.py", line 57, in unload
AttributeError: 'Context' object has no attribute 'disable'
01-20 18:52:29 DEBUG [~] /Users/evan/.talon/user/python.py
01-20 18:52:29 ERROR user.python (/Users/evan/.talon/user/python.py) unload failed
Traceback (most recent call last):
  File "/Applications/Talon.app/Contents/Resources/loader.py", line 24, in load
    module.unload()
  File "/Users/evan/.talon/user/python.py", line 55, in unload
    ctx.disable()
AttributeError: 'Context' object has no attribute 'disable'
01-20 18:52:36 DEBUG [~] /Users/evan/.talon/user/python.py
01-20 18:52:36 ERROR user.python (/Users/evan/.talon/user/python.py) unload failed
Traceback (most recent call last):
  File "/Applications/Talon.app/Contents/Resources/loader.py", line 24, in load
    module.unload()
  File "/Users/evan/.talon/user/python.py", line 55, in unload
    ctx.disable()
AttributeError: 'Context' object has no attribute 'disable'
01-20 18:55:48 DEBUG [~] /Users/evan/.talon/user/vim.py
01-20 18:55:48 ERROR user.vim (/Users/evan/.talon/user/vim.py) unload failed
Traceback (most recent call last):
  File "/Applications/Talon.app/Contents/Resources/loader.py", line 24, in load
    module.unload()
  File "/Users/evan/.talon/user/vim.py", line 133, in unload
    ctx.disable()
AttributeError: 'Context' object has no attribute 'disable'
01-20 18:55:55 DEBUG [~] /Users/evan/.talon/user/vim.py
01-20 18:55:55 ERROR user.vim (/Users/evan/.talon/user/vim.py) unload failed
Traceback (most recent call last):
  File "/Applications/Talon.app/Contents/Resources/loader.py", line 24, in load
    module.unload()
  File "/Users/evan/.talon/user/vim.py", line 133, in unload
    ctx.disable()
AttributeError: 'Context' object has no attribute 'disable'
01-20 18:57:03 DEBUG [~] /Users/evan/.talon/user/vim.py
01-20 18:57:03 ERROR user.vim (/Users/evan/.talon/user/vim.py) unload failed
Traceback (most recent call last):
  File "/Applications/Talon.app/Contents/Resources/loader.py", line 24, in load
    module.unload()
  File "/Users/evan/.talon/user/vim.py", line 133, in unload
AttributeError: 'Context' object has no attribute 'disable'
01-20 19:03:36 DEBUG [~] /Users/evan/.talon/user/std.py
01-20 19:04:05 DEBUG [~] /Users/evan/.talon/user/vim.py
01-20 19:04:05 ERROR user.vim (/Users/evan/.talon/user/vim.py) unload failed
Traceback (most recent call last):
  File "/Applications/Talon.app/Contents/Resources/loader.py", line 24, in load
    module.unload()
  File "/Users/evan/.talon/user/vim.py", line 132, in unload
AttributeError: 'Context' object has no attribute 'disable'
01-20 19:04:09 DEBUG [~] /Users/evan/.talon/user/std.py
01-20 19:05:45 DEBUG [~] /Users/evan/.talon/user/std.py
01-20 19:21:28 DEBUG [~] /Users/evan/.talon/user/bash.py
01-20 19:21:28 ERROR user.bash (/Users/evan/.talon/user/bash.py) unload failed
Traceback (most recent call last):
  File "/Applications/Talon.app/Contents/Resources/loader.py", line 24, in load
    module.unload()
  File "/Users/evan/.talon/user/bash.py", line 23, in unload
    'var disco'     : "/Users/evan/Software/stunning-disco",
AttributeError: 'Context' object has no attribute 'disable'
01-20 19:28:20 DEBUG [~] /Users/evan/.talon/user/bash.py
01-20 19:28:20 ERROR user.bash (/Users/evan/.talon/user/bash.py) unload failed
Traceback (most recent call last):
  File "/Applications/Talon.app/Contents/Resources/loader.py", line 24, in load
    module.unload()
  File "/Users/evan/.talon/user/bash.py", line 38, in unload
    ctx.disable()
AttributeError: 'Context' object has no attribute 'disable'
01-20 19:30:02 DEBUG [~] /Users/evan/.talon/user/bash.py
01-20 19:30:02 ERROR user.bash (/Users/evan/.talon/user/bash.py) unload failed
Traceback (most recent call last):
  File "/Applications/Talon.app/Contents/Resources/loader.py", line 24, in load
    module.unload()
  File "/Users/evan/.talon/user/bash.py", line 38, in unload
AttributeError: 'Context' object has no attribute 'disable'
01-20 19:30:05 DEBUG [~] /Users/evan/.talon/user/bash.py
01-20 19:30:05 ERROR user.bash (/Users/evan/.talon/user/bash.py) unload failed
Traceback (most recent call last):
  File "/Applications/Talon.app/Contents/Resources/loader.py", line 24, in load
    module.unload()
  File "/Users/evan/.talon/user/bash.py", line 37, in unload
    ctx.disable()
AttributeError: 'Context' object has no attribute 'disable'
01-20 19:32:43 ERROR cb error <class 'talon.ui.Mon'> cb=<bound method Collection.ui_event of <talon.voice.Collection object at 0x000000010d363088>> topic="win_title"
Traceback (most recent call last):
  File "/Applications/Talon.app/Contents/Resources/pypy/site-packages/talon/dispatch.py", line 22, in safe_call
    cb(topic, msg)
  File "/Applications/Talon.app/Contents/Resources/pypy/site-packages/talon/voice.py", line 206, in ui_event
    self.update_scope()
  File "/Applications/Talon.app/Contents/Resources/pypy/site-packages/talon/voice.py", line 214, in update_scope
    self.reload()
  File "/Applications/Talon.app/Contents/Resources/pypy/site-packages/talon/voice.py", line 199, in reload
    engine.load(self.grammar)
  File "/Applications/Talon.app/Contents/Resources/pypy/site-packages/talon/engine.py", line 110, in load
    resp = grammar.load(self)
  File "/Applications/Talon.app/Contents/Resources/pypy/site-packages/talon/grammar.py", line 108, in load
    return self.cmd('g.load', main_rule='{}::main'.format(self.name), data=self.grammar.data)
  File "/Applications/Talon.app/Contents/Resources/pypy/site-packages/talon/grammar.py", line 128, in cmd
    return self.engine.cmd(cmd, **kwargs)
  File "/Applications/Talon.app/Contents/Resources/pypy/site-packages/talon/engine.py", line 98, in cmd
    raise EngineCmdErr('engine command "{}" failed'.format(cmd))
talon.engine.EngineCmdErr: engine command "g.load" failed
01-20 19:33:03  INFO Talon starting with /Users/evan/.talon
01-20 19:33:03 DEBUG [+] /Applications/Talon.app/Contents/Resources/plugins/eye.py
01-20 19:33:03 ERROR eye (/Applications/Talon.app/Contents/Resources/plugins/eye.py) import failed
Traceback (most recent call last):
  File "/Applications/Talon.app/Contents/Resources/loader.py", line 40, in load
    spec.loader.exec_module(module)
  File "<builtin>/frozen importlib._bootstrap_external", line 686, in exec_module
  File "<frozen importlib._bootstrap>", line 223, in _call_with_frames_removed
  File "/Applications/Talon.app/Contents/Resources/plugins/eye.py", line 158, in <module>
    tracker = eye.Eye()
  File "/Applications/Talon.app/Contents/Resources/pypy/site-packages/talon/eye.py", line 138, in __init__
    raise EyeOpenErr('Eye Tracker failed to open')
talon.eye.EyeOpenErr: Eye Tracker failed to open
01-20 19:33:03 DEBUG [+] /Applications/Talon.app/Contents/Resources/plugins/repl.py
01-20 19:33:04 DEBUG [+] /Users/evan/.talon/user/bash.py
01-20 19:33:04 DEBUG [+] /Users/evan/.talon/user/python.py
01-20 19:33:04 DEBUG [+] /Users/evan/.talon/user/std.py
01-20 19:33:04 DEBUG [+] /Users/evan/.talon/user/vim.py
01-20 19:35:20 DEBUG [~] /Users/evan/.talon/user/bash.py
01-20 19:35:20 ERROR user.bash (/Users/evan/.talon/user/bash.py) unload failed
Traceback (most recent call last):
  File "/Applications/Talon.app/Contents/Resources/loader.py", line 24, in load
    module.unload()
  File "/Users/evan/.talon/user/bash.py", line 37, in unload
    ctx.disable()
AttributeError: 'Context' object has no attribute 'disable'
01-20 19:36:19 DEBUG [~] /Users/evan/.talon/user/bash.py
01-20 19:36:19 ERROR user.bash (/Users/evan/.talon/user/bash.py) unload failed
Traceback (most recent call last):
  File "/Applications/Talon.app/Contents/Resources/loader.py", line 24, in load
    module.unload()
  File "/Users/evan/.talon/user/bash.py", line 37, in unload
    ctx.disable()
AttributeError: 'Context' object has no attribute 'disable'
01-20 19:37:16 DEBUG [~] /Users/evan/.talon/user/std.py
01-20 19:41:04 DEBUG [~] /Users/evan/.talon/user/bash.py
01-20 19:41:04 ERROR user.bash (/Users/evan/.talon/user/bash.py) unload failed
Traceback (most recent call last):
  File "/Applications/Talon.app/Contents/Resources/loader.py", line 24, in load
    module.unload()
  File "/Users/evan/.talon/user/bash.py", line 37, in unload
    def unload():
AttributeError: 'Context' object has no attribute 'disable'
01-20 19:41:05 DEBUG [~] /Users/evan/.talon/user/bash.py
01-20 19:41:05 ERROR user.bash (/Users/evan/.talon/user/bash.py) unload failed
Traceback (most recent call last):
  File "/Applications/Talon.app/Contents/Resources/loader.py", line 24, in load
    module.unload()
  File "/Users/evan/.talon/user/bash.py", line 38, in unload
    ctx.disable()
AttributeError: 'Context' object has no attribute 'disable'
01-20 19:41:34 DEBUG [~] /Users/evan/.talon/user/bash.py
01-20 19:41:34 ERROR user.bash (/Users/evan/.talon/user/bash.py) unload failed
Traceback (most recent call last):
  File "/Applications/Talon.app/Contents/Resources/loader.py", line 24, in load
    module.unload()
  File "/Users/evan/.talon/user/bash.py", line 38, in unload
    ctx.disable()
AttributeError: 'Context' object has no attribute 'disable'
01-20 19:43:06 DEBUG [~] /Users/evan/.talon/user/bash.py
01-20 19:43:06 ERROR user.bash (/Users/evan/.talon/user/bash.py) unload failed
Traceback (most recent call last):
  File "/Applications/Talon.app/Contents/Resources/loader.py", line 24, in load
    module.unload()
  File "/Users/evan/.talon/user/bash.py", line 38, in unload
    def unload():
AttributeError: 'Context' object has no attribute 'disable'
01-20 19:44:15 DEBUG [~] /Users/evan/.talon/user/bash.py
01-20 19:44:15 ERROR user.bash (/Users/evan/.talon/user/bash.py) unload failed
Traceback (most recent call last):
  File "/Applications/Talon.app/Contents/Resources/loader.py", line 24, in load
    module.unload()
  File "/Users/evan/.talon/user/bash.py", line 39, in unload
    ctx.disable()
AttributeError: 'Context' object has no attribute 'disable'
01-20 19:47:18 DEBUG [~] /Users/evan/.talon/user/bash.py
01-20 19:47:18 ERROR user.bash (/Users/evan/.talon/user/bash.py) unload failed
Traceback (most recent call last):
  File "/Applications/Talon.app/Contents/Resources/loader.py", line 24, in load
    module.unload()
  File "/Users/evan/.talon/user/bash.py", line 39, in unload
    def unload():
AttributeError: 'Context' object has no attribute 'disable'
01-20 19:47:40 DEBUG [~] /Users/evan/.talon/user/bash.py
01-20 19:47:40 ERROR user.bash (/Users/evan/.talon/user/bash.py) unload failed
Traceback (most recent call last):
  File "/Applications/Talon.app/Contents/Resources/loader.py", line 24, in load
    module.unload()
  File "/Users/evan/.talon/user/bash.py", line 40, in unload
    ctx.disable()
AttributeError: 'Context' object has no attribute 'disable'
01-20 19:48:40 DEBUG [~] /Users/evan/.talon/user/bash.py
01-20 19:48:40 ERROR user.bash (/Users/evan/.talon/user/bash.py) unload failed
Traceback (most recent call last):
  File "/Applications/Talon.app/Contents/Resources/loader.py", line 24, in load
    module.unload()
  File "/Users/evan/.talon/user/bash.py", line 40, in unload
    ctx.disable()
AttributeError: 'Context' object has no attribute 'disable'
01-20 19:51:20 DEBUG [~] /Users/evan/.talon/user/bash.py
01-20 19:51:20 ERROR user.bash (/Users/evan/.talon/user/bash.py) unload failed
Traceback (most recent call last):
  File "/Applications/Talon.app/Contents/Resources/loader.py", line 24, in load
    module.unload()
  File "/Users/evan/.talon/user/bash.py", line 40, in unload
    ctx.disable()
AttributeError: 'Context' object has no attribute 'disable'
01-20 20:08:23  INFO Talon starting with /Users/evan/.talon
01-20 20:08:23 DEBUG [+] /Applications/Talon.app/Contents/Resources/plugins/eye.py
01-20 20:08:24 ERROR eye (/Applications/Talon.app/Contents/Resources/plugins/eye.py) import failed
Traceback (most recent call last):
  File "/Applications/Talon.app/Contents/Resources/loader.py", line 40, in load
    spec.loader.exec_module(module)
  File "<builtin>/frozen importlib._bootstrap_external", line 686, in exec_module
  File "<frozen importlib._bootstrap>", line 223, in _call_with_frames_removed
  File "/Applications/Talon.app/Contents/Resources/plugins/eye.py", line 158, in <module>
    tracker = eye.Eye()
  File "/Applications/Talon.app/Contents/Resources/pypy/site-packages/talon/eye.py", line 138, in __init__
    raise EyeOpenErr('Eye Tracker failed to open')
talon.eye.EyeOpenErr: Eye Tracker failed to open
01-20 20:08:24 DEBUG [+] /Applications/Talon.app/Contents/Resources/plugins/repl.py
01-20 20:08:24 DEBUG [+] /Users/evan/.talon/user/bash.py
01-20 20:08:24 DEBUG [+] /Users/evan/.talon/user/python.py
01-20 20:08:24 DEBUG [+] /Users/evan/.talon/user/std.py
01-20 20:08:24 DEBUG [+] /Users/evan/.talon/user/vim.py
01-20 20:14:39 DEBUG [~] /Users/evan/.talon/user/vim.py
01-20 20:14:39 ERROR user.vim (/Users/evan/.talon/user/vim.py) unload failed
Traceback (most recent call last):
  File "/Applications/Talon.app/Contents/Resources/loader.py", line 24, in load
    module.unload()
  File "/Users/evan/.talon/user/vim.py", line 130, in unload
    def unload():
AttributeError: 'Context' object has no attribute 'disable'
01-20 20:18:11 DEBUG [~] /Users/evan/.talon/user/vim.py
01-20 20:18:11 ERROR user.vim (/Users/evan/.talon/user/vim.py) unload failed
Traceback (most recent call last):
  File "/Applications/Talon.app/Contents/Resources/loader.py", line 24, in load
    module.unload()
  File "/Users/evan/.talon/user/vim.py", line 131, in unload
    ctx.disable()
AttributeError: 'Context' object has no attribute 'disable'
01-20 20:18:11 ERROR user.vim (/Users/evan/.talon/user/vim.py) reload failed
Traceback (most recent call last):
  File "/Applications/Talon.app/Contents/Resources/loader.py", line 28, in load
    module = importlib.reload(self[path])
  File "/Applications/Talon.app/Contents/Resources/pypy/lib-python/3/importlib/__init__.py", line 166, in reload
    _bootstrap._exec(spec, module)
  File "<frozen importlib._bootstrap>", line 627, in _exec
  File "<builtin>/frozen importlib._bootstrap_external", line 686, in exec_module
  File "<frozen importlib._bootstrap>", line 223, in _call_with_frames_removed
  File "/Users/evan/.talon/user/vim.py", line 51, in <module>
    'write it quit it (split | window)' : Key('escape %s w %s q' % LEADER),
TypeError: not enough arguments for format string
01-20 20:19:59 DEBUG [~] /Users/evan/.talon/user/vim.py
01-20 20:19:59 ERROR user.vim (/Users/evan/.talon/user/vim.py) unload failed
Traceback (most recent call last):
  File "/Applications/Talon.app/Contents/Resources/loader.py", line 24, in load
    module.unload()
  File "/Users/evan/.talon/user/vim.py", line 131, in unload
    ctx.disable()
AttributeError: 'Context' object has no attribute 'disable'
01-20 20:19:59 ERROR user.vim (/Users/evan/.talon/user/vim.py) reload failed
Traceback (most recent call last):
  File "/Applications/Talon.app/Contents/Resources/loader.py", line 28, in load
    module = importlib.reload(self[path])
  File "/Applications/Talon.app/Contents/Resources/pypy/lib-python/3/importlib/__init__.py", line 166, in reload
    _bootstrap._exec(spec, module)
  File "<frozen importlib._bootstrap>", line 627, in _exec
  File "<builtin>/frozen importlib._bootstrap_external", line 686, in exec_module
  File "<frozen importlib._bootstrap>", line 223, in _call_with_frames_removed
  File "/Users/evan/.talon/user/vim.py", line 51, in <module>
    'write it quit it (split | window)' : Key('escape %s w %s q' % LEADER),
TypeError: not enough arguments for format string
01-20 20:20:28 DEBUG [~] /Users/evan/.talon/user/vim.py
01-20 20:20:28 ERROR user.vim (/Users/evan/.talon/user/vim.py) unload failed
Traceback (most recent call last):
  File "/Applications/Talon.app/Contents/Resources/loader.py", line 24, in load
    module.unload()
  File "/Users/evan/.talon/user/vim.py", line 131, in unload
    ctx.disable()
AttributeError: 'Context' object has no attribute 'disable'
01-20 20:20:28 ERROR user.vim (/Users/evan/.talon/user/vim.py) reload failed
Traceback (most recent call last):
  File "/Applications/Talon.app/Contents/Resources/loader.py", line 28, in load
    module = importlib.reload(self[path])
  File "/Applications/Talon.app/Contents/Resources/pypy/lib-python/3/importlib/__init__.py", line 166, in reload
    _bootstrap._exec(spec, module)
  File "<frozen importlib._bootstrap>", line 627, in _exec
  File "<builtin>/frozen importlib._bootstrap_external", line 686, in exec_module
  File "<frozen importlib._bootstrap>", line 223, in _call_with_frames_removed
  File "/Users/evan/.talon/user/vim.py", line 51, in <module>
    'write it quit it (split | window)' : Key('escape %s w %s q' % LEADER),
TypeError: not enough arguments for format string
01-20 20:20:32 DEBUG [~] /Users/evan/.talon/user/vim.py
01-20 20:20:32 ERROR user.vim (/Users/evan/.talon/user/vim.py) unload failed
Traceback (most recent call last):
  File "/Applications/Talon.app/Contents/Resources/loader.py", line 24, in load
    module.unload()
  File "/Users/evan/.talon/user/vim.py", line 131, in unload
    ctx.disable()
AttributeError: 'Context' object has no attribute 'disable'
01-20 20:20:32 ERROR user.vim (/Users/evan/.talon/user/vim.py) reload failed
Traceback (most recent call last):
  File "/Applications/Talon.app/Contents/Resources/loader.py", line 28, in load
    module = importlib.reload(self[path])
  File "/Applications/Talon.app/Contents/Resources/pypy/lib-python/3/importlib/__init__.py", line 166, in reload
    _bootstrap._exec(spec, module)
  File "<frozen importlib._bootstrap>", line 627, in _exec
  File "<builtin>/frozen importlib._bootstrap_external", line 686, in exec_module
  File "<frozen importlib._bootstrap>", line 223, in _call_with_frames_removed
  File "/Users/evan/.talon/user/vim.py", line 51, in <module>
    'write it quit it (split | window)' : Key('escape %s w %s q' % LEADER),
TypeError: not enough arguments for format string
01-20 20:20:50 DEBUG [~] /Users/evan/.talon/user/vim.py
01-20 20:20:50 ERROR user.vim (/Users/evan/.talon/user/vim.py) unload failed
Traceback (most recent call last):
  File "/Applications/Talon.app/Contents/Resources/loader.py", line 24, in load
    module.unload()
  File "/Users/evan/.talon/user/vim.py", line 131, in unload
    ctx.disable()
AttributeError: 'Context' object has no attribute 'disable'
01-20 20:20:50 ERROR user.vim (/Users/evan/.talon/user/vim.py) reload failed
Traceback (most recent call last):
  File "/Applications/Talon.app/Contents/Resources/loader.py", line 28, in load
    module = importlib.reload(self[path])
  File "/Applications/Talon.app/Contents/Resources/pypy/lib-python/3/importlib/__init__.py", line 166, in reload
    _bootstrap._exec(spec, module)
  File "<frozen importlib._bootstrap>", line 627, in _exec
  File "<builtin>/frozen importlib._bootstrap_external", line 686, in exec_module
  File "<frozen importlib._bootstrap>", line 223, in _call_with_frames_removed
  File "/Users/evan/.talon/user/vim.py", line 51, in <module>
    'write it quit it (split | window)' : Key('escape %s w %s q' % LEADER),
TypeError: not enough arguments for format string
01-20 20:21:50 DEBUG [~] /Users/evan/.talon/user/vim.py
01-20 20:21:50 ERROR user.vim (/Users/evan/.talon/user/vim.py) unload failed
Traceback (most recent call last):
  File "/Applications/Talon.app/Contents/Resources/loader.py", line 24, in load
    module.unload()
  File "/Users/evan/.talon/user/vim.py", line 131, in unload
AttributeError: 'Context' object has no attribute 'disable'
01-20 20:23:41 DEBUG [~] /Users/evan/.talon/user/vim.py
01-20 20:23:41 ERROR user.vim (/Users/evan/.talon/user/vim.py) unload failed
Traceback (most recent call last):
  File "/Applications/Talon.app/Contents/Resources/loader.py", line 24, in load
    module.unload()
  File "/Users/evan/.talon/user/vim.py", line 130, in unload
    def unload():
AttributeError: 'Context' object has no attribute 'disable'
01-20 20:23:41 ERROR user.vim (/Users/evan/.talon/user/vim.py) reload failed
Traceback (most recent call last):
  File "/Applications/Talon.app/Contents/Resources/loader.py", line 28, in load
    module = importlib.reload(self[path])
  File "/Applications/Talon.app/Contents/Resources/pypy/lib-python/3/importlib/__init__.py", line 166, in reload
    _bootstrap._exec(spec, module)
  File "<frozen importlib._bootstrap>", line 627, in _exec
  File "<builtin>/frozen importlib._bootstrap_external", line 686, in exec_module
  File "<frozen importlib._bootstrap>", line 223, in _call_with_frames_removed
  File "/Users/evan/.talon/user/vim.py", line 50, in <module>
    'write it quit it'         : Key('escape %s w %s q' % LEADER),
TypeError: not enough arguments for format string
01-20 20:24:43 DEBUG [~] /Users/evan/.talon/user/vim.py
01-20 20:24:43 ERROR user.vim (/Users/evan/.talon/user/vim.py) unload failed
Traceback (most recent call last):
  File "/Applications/Talon.app/Contents/Resources/loader.py", line 24, in load
    module.unload()
  File "/Users/evan/.talon/user/vim.py", line 130, in unload
    def unload():
AttributeError: 'Context' object has no attribute 'disable'
01-20 20:24:47 DEBUG [~] /Users/evan/.talon/user/vim.py
01-20 20:24:47 ERROR user.vim (/Users/evan/.talon/user/vim.py) unload failed
Traceback (most recent call last):
  File "/Applications/Talon.app/Contents/Resources/loader.py", line 24, in load
    module.unload()
  File "/Users/evan/.talon/user/vim.py", line 131, in unload
    ctx.disable()
AttributeError: 'Context' object has no attribute 'disable'
01-20 20:24:48 DEBUG [~] /Users/evan/.talon/user/vim.py
01-20 20:24:48 ERROR user.vim (/Users/evan/.talon/user/vim.py) unload failed
Traceback (most recent call last):
  File "/Applications/Talon.app/Contents/Resources/loader.py", line 24, in load
    module.unload()
  File "/Users/evan/.talon/user/vim.py", line 131, in unload
    ctx.disable()
AttributeError: 'Context' object has no attribute 'disable'
01-20 20:25:45 DEBUG [~] /Users/evan/.talon/user/vim.py
01-20 20:25:45 ERROR user.vim (/Users/evan/.talon/user/vim.py) unload failed
Traceback (most recent call last):
  File "/Applications/Talon.app/Contents/Resources/loader.py", line 24, in load
    module.unload()
  File "/Users/evan/.talon/user/vim.py", line 131, in unload
    ctx.disable()
AttributeError: 'Context' object has no attribute 'disable'
01-20 20:39:37 DEBUG [~] /Users/evan/.talon/user/vim.py
01-20 20:39:37 ERROR user.vim (/Users/evan/.talon/user/vim.py) unload failed
Traceback (most recent call last):
  File "/Applications/Talon.app/Contents/Resources/loader.py", line 24, in load
    module.unload()
  File "/Users/evan/.talon/user/vim.py", line 131, in unload
    def unload():
AttributeError: 'Context' object has no attribute 'disable'
01-20 20:41:16 DEBUG [~] /Users/evan/.talon/user/vim.py
01-20 20:41:16 ERROR user.vim (/Users/evan/.talon/user/vim.py) unload failed
Traceback (most recent call last):
  File "/Applications/Talon.app/Contents/Resources/loader.py", line 24, in load
    module.unload()
  File "/Users/evan/.talon/user/vim.py", line 132, in unload
AttributeError: 'Context' object has no attribute 'disable'
01-20 20:44:53 DEBUG [~] /Users/evan/.talon/user/bash.py
01-20 20:44:53 ERROR user.bash (/Users/evan/.talon/user/bash.py) unload failed
Traceback (most recent call last):
  File "/Applications/Talon.app/Contents/Resources/loader.py", line 24, in load
    module.unload()
  File "/Users/evan/.talon/user/bash.py", line 40, in unload
AttributeError: 'Context' object has no attribute 'disable'
01-20 20:44:53 ERROR user.bash (/Users/evan/.talon/user/bash.py) reload failed
Traceback (most recent call last):
  File "/Applications/Talon.app/Contents/Resources/loader.py", line 28, in load
    module = importlib.reload(self[path])
  File "/Applications/Talon.app/Contents/Resources/pypy/lib-python/3/importlib/__init__.py", line 166, in reload
    _bootstrap._exec(spec, module)
  File "<frozen importlib._bootstrap>", line 627, in _exec
  File "<builtin>/frozen importlib._bootstrap_external", line 682, in exec_module
  File "<builtin>/frozen importlib._bootstrap_external", line 788, in get_code
  File "<builtin>/frozen importlib._bootstrap_external", line 748, in source_to_code
  File "<frozen importlib._bootstrap>", line 223, in _call_with_frames_removed
  File "/Users/evan/.talon/user/bash.py", line 4
    from .vim import
                    ^
SyntaxError: invalid syntax
01-20 20:44:58 DEBUG [~] /Users/evan/.talon/user/bash.py
01-20 20:44:58 ERROR user.bash (/Users/evan/.talon/user/bash.py) unload failed
Traceback (most recent call last):
  File "/Applications/Talon.app/Contents/Resources/loader.py", line 24, in load
    module.unload()
  File "/Users/evan/.talon/user/bash.py", line 40, in unload
AttributeError: 'Context' object has no attribute 'disable'
01-20 20:45:02 DEBUG [~] /Users/evan/.talon/user/bash.py
01-20 20:45:02 ERROR user.bash (/Users/evan/.talon/user/bash.py) unload failed
Traceback (most recent call last):
  File "/Applications/Talon.app/Contents/Resources/loader.py", line 24, in load
    module.unload()
  File "/Users/evan/.talon/user/bash.py", line 44, in unload
    ctx.disable()
AttributeError: 'Context' object has no attribute 'disable'
01-20 20:53:36 DEBUG [~] /Users/evan/.talon/user/bash.py
01-20 20:53:36 ERROR user.bash (/Users/evan/.talon/user/bash.py) unload failed
Traceback (most recent call last):
  File "/Applications/Talon.app/Contents/Resources/loader.py", line 24, in load
    module.unload()
  File "/Users/evan/.talon/user/bash.py", line 44, in unload
    bashmap.update(common_to_bash)
AttributeError: 'Context' object has no attribute 'disable'
01-20 20:54:57 DEBUG [~] /Users/evan/.talon/user/bash.py
01-20 20:54:57 ERROR user.bash (/Users/evan/.talon/user/bash.py) unload failed
Traceback (most recent call last):
  File "/Applications/Talon.app/Contents/Resources/loader.py", line 24, in load
    module.unload()
  File "/Users/evan/.talon/user/bash.py", line 49, in unload
    ctx.disable()
AttributeError: 'Context' object has no attribute 'disable'
01-20 20:56:23 DEBUG [~] /Users/evan/.talon/user/bash.py
01-20 20:56:23 ERROR user.bash (/Users/evan/.talon/user/bash.py) unload failed
Traceback (most recent call last):
  File "/Applications/Talon.app/Contents/Resources/loader.py", line 24, in load
    module.unload()
  File "/Users/evan/.talon/user/bash.py", line 49, in unload
    ctx.disable()
AttributeError: 'Context' object has no attribute 'disable'
01-20 21:02:08 DEBUG [~] /Users/evan/.talon/user/bash.py
01-20 21:02:08 ERROR user.bash (/Users/evan/.talon/user/bash.py) unload failed
Traceback (most recent call last):
  File "/Applications/Talon.app/Contents/Resources/loader.py", line 24, in load
    module.unload()
  File "/Users/evan/.talon/user/bash.py", line 49, in unload
    ctx.disable()
AttributeError: 'Context' object has no attribute 'disable'
01-20 21:03:11 ERROR cb error <class 'talon.ui.Mon'> cb=<bound method Collection.ui_event of <talon.voice.Collection object at 0x00000001177377c0>> topic="win_title"
Traceback (most recent call last):
  File "/Applications/Talon.app/Contents/Resources/pypy/site-packages/talon/dispatch.py", line 22, in safe_call
    cb(topic, msg)
  File "/Applications/Talon.app/Contents/Resources/pypy/site-packages/talon/voice.py", line 206, in ui_event
    self.update_scope()
  File "/Applications/Talon.app/Contents/Resources/pypy/site-packages/talon/voice.py", line 214, in update_scope
    self.reload()
  File "/Applications/Talon.app/Contents/Resources/pypy/site-packages/talon/voice.py", line 199, in reload
    engine.load(self.grammar)
  File "/Applications/Talon.app/Contents/Resources/pypy/site-packages/talon/engine.py", line 110, in load
    resp = grammar.load(self)
  File "/Applications/Talon.app/Contents/Resources/pypy/site-packages/talon/grammar.py", line 108, in load
    return self.cmd('g.load', main_rule='{}::main'.format(self.name), data=self.grammar.data)
  File "/Applications/Talon.app/Contents/Resources/pypy/site-packages/talon/grammar.py", line 128, in cmd
    return self.engine.cmd(cmd, **kwargs)
  File "/Applications/Talon.app/Contents/Resources/pypy/site-packages/talon/engine.py", line 98, in cmd
    raise EngineCmdErr('engine command "{}" failed'.format(cmd))
talon.engine.EngineCmdErr: engine command "g.load" failed
01-20 21:03:11 DEBUG [~] /Users/evan/.talon/user/bash.py
01-20 21:03:11 ERROR user.bash (/Users/evan/.talon/user/bash.py) unload failed
Traceback (most recent call last):
  File "/Applications/Talon.app/Contents/Resources/loader.py", line 24, in load
    module.unload()
  File "/Users/evan/.talon/user/bash.py", line 49, in unload
    ctx.disable()
AttributeError: 'Context' object has no attribute 'disable'
01-20 21:03:11 ERROR user.bash (/Users/evan/.talon/user/bash.py) reload failed
Traceback (most recent call last):
  File "/Applications/Talon.app/Contents/Resources/loader.py", line 28, in load
    module = importlib.reload(self[path])
  File "/Applications/Talon.app/Contents/Resources/pypy/lib-python/3/importlib/__init__.py", line 166, in reload
    _bootstrap._exec(spec, module)
  File "<frozen importlib._bootstrap>", line 627, in _exec
  File "<builtin>/frozen importlib._bootstrap_external", line 686, in exec_module
  File "<frozen importlib._bootstrap>", line 223, in _call_with_frames_removed
  File "/Users/evan/.talon/user/bash.py", line 2, in <module>
    ctx = Context('bash', bundle='com.googlecode.iterm2', func=lambda app, win: 'bash' in win.title)
  File "/Applications/Talon.app/Contents/Resources/pypy/site-packages/talon/voice.py", line 241, in __init__
    self.load()
  File "/Applications/Talon.app/Contents/Resources/pypy/site-packages/talon/voice.py", line 243, in load
    def load(self): collection.add(self)
  File "/Applications/Talon.app/Contents/Resources/pypy/site-packages/talon/voice.py", line 218, in add
    self.update_scope()
  File "/Applications/Talon.app/Contents/Resources/pypy/site-packages/talon/voice.py", line 214, in update_scope
    self.reload()
  File "/Applications/Talon.app/Contents/Resources/pypy/site-packages/talon/voice.py", line 176, in reload
    self.grammar.unload()
  File "/Applications/Talon.app/Contents/Resources/pypy/site-packages/talon/grammar.py", line 112, in unload
    def unload(self):  return self.engine.unload(self.name)
  File "/Applications/Talon.app/Contents/Resources/pypy/site-packages/talon/engine.py", line 115, in unload
    resp = self.cmd('g.unload', name=name)
  File "/Applications/Talon.app/Contents/Resources/pypy/site-packages/talon/engine.py", line 98, in cmd
    raise EngineCmdErr('engine command "{}" failed'.format(cmd))
talon.engine.EngineCmdErr: engine command "g.unload" failed
01-20 21:03:22 ERROR cb error <class 'talon.ui.Mon'> cb=<bound method Collection.ui_event of <talon.voice.Collection object at 0x00000001177377c0>> topic="win_title"
Traceback (most recent call last):
  File "/Applications/Talon.app/Contents/Resources/pypy/site-packages/talon/dispatch.py", line 22, in safe_call
    cb(topic, msg)
  File "/Applications/Talon.app/Contents/Resources/pypy/site-packages/talon/voice.py", line 206, in ui_event
    self.update_scope()
  File "/Applications/Talon.app/Contents/Resources/pypy/site-packages/talon/voice.py", line 214, in update_scope
    self.reload()
  File "/Applications/Talon.app/Contents/Resources/pypy/site-packages/talon/voice.py", line 176, in reload
    self.grammar.unload()
  File "/Applications/Talon.app/Contents/Resources/pypy/site-packages/talon/grammar.py", line 112, in unload
    def unload(self):  return self.engine.unload(self.name)
  File "/Applications/Talon.app/Contents/Resources/pypy/site-packages/talon/engine.py", line 115, in unload
    resp = self.cmd('g.unload', name=name)
  File "/Applications/Talon.app/Contents/Resources/pypy/site-packages/talon/engine.py", line 98, in cmd
    raise EngineCmdErr('engine command "{}" failed'.format(cmd))
talon.engine.EngineCmdErr: engine command "g.unload" failed
01-20 21:03:50 ERROR cb error <class 'talon.ui.Mon'> cb=<bound method Collection.ui_event of <talon.voice.Collection object at 0x00000001177377c0>> topic="win_title"
Traceback (most recent call last):
  File "/Applications/Talon.app/Contents/Resources/pypy/site-packages/talon/dispatch.py", line 22, in safe_call
    cb(topic, msg)
  File "/Applications/Talon.app/Contents/Resources/pypy/site-packages/talon/voice.py", line 206, in ui_event
    self.update_scope()
  File "/Applications/Talon.app/Contents/Resources/pypy/site-packages/talon/voice.py", line 214, in update_scope
    self.reload()
  File "/Applications/Talon.app/Contents/Resources/pypy/site-packages/talon/voice.py", line 176, in reload
    self.grammar.unload()
  File "/Applications/Talon.app/Contents/Resources/pypy/site-packages/talon/grammar.py", line 112, in unload
    def unload(self):  return self.engine.unload(self.name)
  File "/Applications/Talon.app/Contents/Resources/pypy/site-packages/talon/engine.py", line 115, in unload
    resp = self.cmd('g.unload', name=name)
  File "/Applications/Talon.app/Contents/Resources/pypy/site-packages/talon/engine.py", line 98, in cmd
    raise EngineCmdErr('engine command "{}" failed'.format(cmd))
talon.engine.EngineCmdErr: engine command "g.unload" failed
01-20 21:03:50 ERROR cb error <class 'talon.ui.Mon'> cb=<bound method Collection.ui_event of <talon.voice.Collection object at 0x00000001177377c0>> topic="win_title"
Traceback (most recent call last):
  File "/Applications/Talon.app/Contents/Resources/pypy/site-packages/talon/dispatch.py", line 22, in safe_call
    cb(topic, msg)
  File "/Applications/Talon.app/Contents/Resources/pypy/site-packages/talon/voice.py", line 206, in ui_event
    self.update_scope()
  File "/Applications/Talon.app/Contents/Resources/pypy/site-packages/talon/voice.py", line 214, in update_scope
    self.reload()
  File "/Applications/Talon.app/Contents/Resources/pypy/site-packages/talon/voice.py", line 176, in reload
    self.grammar.unload()
  File "/Applications/Talon.app/Contents/Resources/pypy/site-packages/talon/grammar.py", line 112, in unload
    def unload(self):  return self.engine.unload(self.name)
  File "/Applications/Talon.app/Contents/Resources/pypy/site-packages/talon/engine.py", line 115, in unload
    resp = self.cmd('g.unload', name=name)
  File "/Applications/Talon.app/Contents/Resources/pypy/site-packages/talon/engine.py", line 98, in cmd
    raise EngineCmdErr('engine command "{}" failed'.format(cmd))
talon.engine.EngineCmdErr: engine command "g.unload" failed
01-20 21:03:52 DEBUG [~] /Users/evan/.talon/user/bash.py
01-20 21:03:52 ERROR user.bash (/Users/evan/.talon/user/bash.py) unload failed
Traceback (most recent call last):
  File "/Applications/Talon.app/Contents/Resources/loader.py", line 24, in load
    module.unload()
  File "/Users/evan/.talon/user/bash.py", line 49, in unload
AttributeError: 'Context' object has no attribute 'disable'
01-20 21:03:52 ERROR user.bash (/Users/evan/.talon/user/bash.py) reload failed
Traceback (most recent call last):
  File "/Applications/Talon.app/Contents/Resources/loader.py", line 28, in load
    module = importlib.reload(self[path])
  File "/Applications/Talon.app/Contents/Resources/pypy/lib-python/3/importlib/__init__.py", line 166, in reload
    _bootstrap._exec(spec, module)
  File "<frozen importlib._bootstrap>", line 627, in _exec
  File "<builtin>/frozen importlib._bootstrap_external", line 686, in exec_module
  File "<frozen importlib._bootstrap>", line 223, in _call_with_frames_removed
  File "/Users/evan/.talon/user/bash.py", line 2, in <module>
    ctx = Context('bash', bundle='com.googlecode.iterm2', func=lambda app, win: 'bash' in win.title)
  File "/Applications/Talon.app/Contents/Resources/pypy/site-packages/talon/voice.py", line 241, in __init__
    self.load()
  File "/Applications/Talon.app/Contents/Resources/pypy/site-packages/talon/voice.py", line 243, in load
    def load(self): collection.add(self)
  File "/Applications/Talon.app/Contents/Resources/pypy/site-packages/talon/voice.py", line 218, in add
    self.update_scope()
  File "/Applications/Talon.app/Contents/Resources/pypy/site-packages/talon/voice.py", line 214, in update_scope
    self.reload()
  File "/Applications/Talon.app/Contents/Resources/pypy/site-packages/talon/voice.py", line 176, in reload
    self.grammar.unload()
  File "/Applications/Talon.app/Contents/Resources/pypy/site-packages/talon/grammar.py", line 112, in unload
    def unload(self):  return self.engine.unload(self.name)
  File "/Applications/Talon.app/Contents/Resources/pypy/site-packages/talon/engine.py", line 115, in unload
    resp = self.cmd('g.unload', name=name)
  File "/Applications/Talon.app/Contents/Resources/pypy/site-packages/talon/engine.py", line 98, in cmd
    raise EngineCmdErr('engine command "{}" failed'.format(cmd))
talon.engine.EngineCmdErr: engine command "g.unload" failed
01-20 21:04:13  INFO Talon starting with /Users/evan/.talon
01-20 21:04:13 DEBUG [+] /Applications/Talon.app/Contents/Resources/plugins/eye.py
01-20 21:04:13 ERROR eye (/Applications/Talon.app/Contents/Resources/plugins/eye.py) import failed
Traceback (most recent call last):
  File "/Applications/Talon.app/Contents/Resources/loader.py", line 40, in load
    spec.loader.exec_module(module)
  File "<builtin>/frozen importlib._bootstrap_external", line 686, in exec_module
  File "<frozen importlib._bootstrap>", line 223, in _call_with_frames_removed
  File "/Applications/Talon.app/Contents/Resources/plugins/eye.py", line 158, in <module>
    tracker = eye.Eye()
  File "/Applications/Talon.app/Contents/Resources/pypy/site-packages/talon/eye.py", line 138, in __init__
    raise EyeOpenErr('Eye Tracker failed to open')
talon.eye.EyeOpenErr: Eye Tracker failed to open
01-20 21:04:13 DEBUG [+] /Applications/Talon.app/Contents/Resources/plugins/repl.py
01-20 21:04:13 DEBUG [+] /Users/evan/.talon/user/bash.py
01-20 21:04:13 DEBUG [+] /Users/evan/.talon/user/python.py
01-20 21:04:13 DEBUG [+] /Users/evan/.talon/user/std.py
01-20 21:04:23 ERROR user.std (/Users/evan/.talon/user/std.py) import failed
Traceback (most recent call last):
  File "/Applications/Talon.app/Contents/Resources/loader.py", line 40, in load
    spec.loader.exec_module(module)
  File "<builtin>/frozen importlib._bootstrap_external", line 686, in exec_module
  File "<frozen importlib._bootstrap>", line 223, in _call_with_frames_removed
  File "/Users/evan/.talon/user/std.py", line 197, in <module>
    ctx.keymap(keymap)
  File "/Applications/Talon.app/Contents/Resources/pypy/site-packages/talon/voice.py", line 305, in keymap
    self.reload()
  File "/Applications/Talon.app/Contents/Resources/pypy/site-packages/talon/voice.py", line 247, in reload
    self.load()
  File "/Applications/Talon.app/Contents/Resources/pypy/site-packages/talon/voice.py", line 243, in load
    def load(self): collection.add(self)
  File "/Applications/Talon.app/Contents/Resources/pypy/site-packages/talon/voice.py", line 218, in add
    self.update_scope()
  File "/Applications/Talon.app/Contents/Resources/pypy/site-packages/talon/voice.py", line 214, in update_scope
    self.reload()
  File "/Applications/Talon.app/Contents/Resources/pypy/site-packages/talon/voice.py", line 199, in reload
    engine.load(self.grammar)
  File "/Applications/Talon.app/Contents/Resources/pypy/site-packages/talon/engine.py", line 110, in load
    resp = grammar.load(self)
  File "/Applications/Talon.app/Contents/Resources/pypy/site-packages/talon/grammar.py", line 108, in load
    return self.cmd('g.load', main_rule='{}::main'.format(self.name), data=self.grammar.data)
  File "/Applications/Talon.app/Contents/Resources/pypy/site-packages/talon/grammar.py", line 128, in cmd
    return self.engine.cmd(cmd, **kwargs)
  File "/Applications/Talon.app/Contents/Resources/pypy/site-packages/talon/engine.py", line 98, in cmd
    raise EngineCmdErr('engine command "{}" failed'.format(cmd))
talon.engine.EngineCmdErr: engine command "g.load" failed
01-20 21:04:23 ERROR cb error <class 'talon.ui.Mon'> cb=<bound method Collection.ui_event of <talon.voice.Collection object at 0x000000011559c170>> topic="app_activate"
Traceback (most recent call last):
  File "/Applications/Talon.app/Contents/Resources/pypy/site-packages/talon/dispatch.py", line 22, in safe_call
    cb(topic, msg)
  File "/Applications/Talon.app/Contents/Resources/pypy/site-packages/talon/voice.py", line 206, in ui_event
    self.update_scope()
  File "/Applications/Talon.app/Contents/Resources/pypy/site-packages/talon/voice.py", line 214, in update_scope
    self.reload()
  File "/Applications/Talon.app/Contents/Resources/pypy/site-packages/talon/voice.py", line 176, in reload
    self.grammar.unload()
  File "/Applications/Talon.app/Contents/Resources/pypy/site-packages/talon/grammar.py", line 112, in unload
    def unload(self):  return self.engine.unload(self.name)
  File "/Applications/Talon.app/Contents/Resources/pypy/site-packages/talon/engine.py", line 115, in unload
    resp = self.cmd('g.unload', name=name)
  File "/Applications/Talon.app/Contents/Resources/pypy/site-packages/talon/engine.py", line 98, in cmd
    raise EngineCmdErr('engine command "{}" failed'.format(cmd))
talon.engine.EngineCmdErr: engine command "g.unload" failed
01-20 21:04:23    IO Exception in thread Thread-3:
Traceback (most recent call last):
  File "/Applications/Talon.app/Contents/Resources/pypy/lib-python/3/threading.py", line 914, in _bootstrap_inner
    self.run()
  File "/Applications/Talon.app/Contents/Resources/pypy/lib-python/3/threading.py", line 862, in run
    self._target(*self._args, **self._kwargs)
  File "/Applications/Talon.app/Contents/Resources/pypy/site-packages/talon/engine.py", line 58, in check_ready
    j = self.cmd('status')
  File "/Applications/Talon.app/Contents/Resources/pypy/site-packages/talon/engine.py", line 98, in cmd
    raise EngineCmdErr('engine command "{}" failed'.format(cmd))
talon.engine.EngineCmdErr: engine command "status" failed
01-20 21:04:23 DEBUG [+] /Users/evan/.talon/user/vim.py
01-20 21:04:23    IO 
01-20 21:04:23 ERROR cb error <class 'talon.ui.Mon'> cb=<bound method Collection.ui_event of <talon.voice.Collection object at 0x000000011559c170>> topic="win_title"
Traceback (most recent call last):
  File "/Applications/Talon.app/Contents/Resources/pypy/site-packages/talon/dispatch.py", line 22, in safe_call
    cb(topic, msg)
  File "/Applications/Talon.app/Contents/Resources/pypy/site-packages/talon/voice.py", line 206, in ui_event
    self.update_scope()
  File "/Applications/Talon.app/Contents/Resources/pypy/site-packages/talon/voice.py", line 214, in update_scope
    self.reload()
  File "/Applications/Talon.app/Contents/Resources/pypy/site-packages/talon/voice.py", line 176, in reload
    self.grammar.unload()
  File "/Applications/Talon.app/Contents/Resources/pypy/site-packages/talon/grammar.py", line 112, in unload
    def unload(self):  return self.engine.unload(self.name)
AttributeError: 'NoneType' object has no attribute 'unload'
01-20 21:07:42 DEBUG [~] /Users/evan/.talon/user/bash.py
01-20 21:07:42 ERROR user.bash (/Users/evan/.talon/user/bash.py) unload failed
Traceback (most recent call last):
  File "/Applications/Talon.app/Contents/Resources/loader.py", line 24, in load
    module.unload()
  File "/Users/evan/.talon/user/bash.py", line 49, in unload
    def unload():
AttributeError: 'Context' object has no attribute 'disable'
